(.venv) PS C:\Users\SaiKrishna\PycharmProjects\pytestgit\newPytest\pytest> pytest
Checking API health at: https://lv-sub-inv-dev-appsvc.azurewebsites.net/subinvapi/graphql/
C:\Users\SaiKrishna\PycharmProjects\pytestgit\pytest\.venv\Lib\site-packages\urllib3\connectionpool.py:1097: InsecureRequestWarning: Unverified HTTPS request is being made to host 'lv-sub-inv-dev-appsvc.azurewebsites.net'. Adding certificate verification is strongly advised. See: https://urllib3.readthedocs.io/en/latest/advanced-usage.html#tls-warnings
  warnings.warn(
Response Status Code: 200
Response Headers: {'Content-Type': 'application/graphql-response+json; charset=utf-8', 'Date': 'Wed, 30 Apr 2025 01:06:10 GMT', 'Server': 'Microsoft-IIS/10.0', 'Set-Cookie': 'ARRAffinity=7d577d29f8e00b2374ddb413016b2f6617c84445e3b963399a9d336135481e13;Path=/;HttpOnly;Secure;Domain=lv-sub-inv-dev-appsvc.azurewebsites.net, ARRAffinitySameSite=7d577d29f8e00b2374ddb413016b2f6617c84445e3b963399a9d336135481e13;Path=/;HttpOnly;SameSite=None;Secure;Domain=lv-sub-inv-dev-appsvc.azurewebsites.net', 'Transfer-Encoding': 'chunked', 'Strict-Transport-Security': 'max-age=2592000', 'Request-Context': 'appId=cid-v1:59368e04-2e6f-4086-9672-604d4ac2de56', 'X-Powered-By': 'ASP.NET'}
Response Body: {"data":{"__typename":"Query"}}...
INTERNALERROR> Traceback (most recent call last):
INTERNALERROR>   File "C:\Users\SaiKrishna\PycharmProjects\pytestgit\pytest\.venv\Lib\site-packages\_pytest\main.py", line 268, in wrap_session
INTERNALERROR>     config._do_configure()
INTERNALERROR>   File "C:\Users\SaiKrishna\PycharmProjects\pytestgit\pytest\.venv\Lib\site-packages\_pytest\config\__init__.py", line 1072, in _do_configure
INTERNALERROR>     self.hook.pytest_configure.call_historic(kwargs=dict(config=self))
INTERNALERROR>   File "C:\Users\SaiKrishna\PycharmProjects\pytestgit\pytest\.venv\Lib\site-packages\pluggy\_hooks.py", line 535, in call_historic
INTERNALERROR>     res = self._hookexec(self.name, self._hookimpls.copy(), kwargs, False)
INTERNALERROR>           ^^^^^^^^^^^^^^^^^^^^^^^^^^^^^^^^^^^^^^^^^^^^^^^^^^^^^^^^^^^^^^^^
INTERNALERROR>   File "C:\Users\SaiKrishna\PycharmProjects\pytestgit\pytest\.venv\Lib\site-packages\pluggy\_manager.py", line 120, in _hookexec
INTERNALERROR>     return self._inner_hookexec(hook_name, methods, kwargs, firstresult)
INTERNALERROR>            ^^^^^^^^^^^^^^^^^^^^^^^^^^^^^^^^^^^^^^^^^^^^^^^^^^^^^^^^^^^^^
INTERNALERROR>   File "C:\Users\SaiKrishna\PycharmProjects\pytestgit\pytest\.venv\Lib\site-packages\pluggy\_callers.py", line 139, in _multicall
INTERNALERROR>     raise exception.with_traceback(exception.__traceback__)
INTERNALERROR>   File "C:\Users\SaiKrishna\PycharmProjects\pytestgit\pytest\.venv\Lib\site-packages\pluggy\_callers.py", line 103, in _multicall
INTERNALERROR>     res = hook_impl.function(*args)
INTERNALERROR>           ^^^^^^^^^^^^^^^^^^^^^^^^^
INTERNALERROR>   File "C:\Users\SaiKrishna\PycharmProjects\pytestgit\newPytest\pytest\conftest.py", line 54, in pytest_configure
INTERNALERROR>     config._metadata['GraphQL API URL'] = os.getenv('API_URL')
INTERNALERROR>     ^^^^^^^^^^^^^^^^
INTERNALERROR> AttributeError: 'Config' object has no attribute '_metadata'
(.venv) PS C:\Users\SaiKrishna\PycharmProjects\pytestgit\newPytest\pytest>

